<?xml version="1.0"?>
<robot name="wheel" xmlns:xacro="http://www.ros.org/wiki/xacro">


  <!-- Parameter -->
  <xacro:property name="M_PI" value="3.1415926535897931" />
  <xacro:property name="Einschlagswinkel" value="${M_PI/8}"/>
  <xacro:property name="degrees_90" value="${M_PI/2}"/>
 
  <!-- hub_dia and tire_dia are the diameters of the hub and tire,
       respectively. hex_hub_depth is the distance that the hex hub is
       inset from the outer edge of the tire. It is set so that each wheel
       is a "zero offset" wheel. hex_hub_depth = tire_width / 2 -
       axle_length. -->
  <xacro:property name="hub_dia" value="${0.09652}"/>
  <xacro:property name="tire_dia" value="${0.14605}"/>
  <xacro:property name="tire_width" value="0.0889"/>
  <xacro:property name="wheel_mass" value="0.29"/>

  <!-- <xacro:property name="hub_dia" value="0.06"/>
  <xacro:property name="tire_dia" value="0.066"/>
  <xacro:property name="tire_width" value="0.027"/>
  <xacro:property name="wheel_mass" value="0.29"/> -->
  <!-- The specifications for a Titan(R) 550 motor could not be found, so the
       stall torque of a Mabuchi Motor(R) RS-550VC-7525 motor was used instead.

       num_spur_gear_teeth = 68
       num_pinion_gear_teeth = 19
       final_gear_ratio = (num_spur_gear_teeth / num_pinion_gear_teeth) *
         5.22 = 18.68
       stall_torque = 0.549 N m
       axle_eff_limit = ((2 * stall_torque) * final_gear_ratio) / 4 =
         5.12766 N m

       max_speed = 40 mph (30+ mph) = 17.8816 m/s
       axle_vel_limit = (2 * pi) * (max_speed / (pi * tire_dia)) =
         244.8696 rad/s -->
  <!-- <xacro:property name="axle_eff_limit" value="5.12766"/>
  <xacro:property name="axle_vel_limit" value="244.8696"/> -->
  <xacro:property name="axle_eff_limit" value="1.12766"/>
  <xacro:property name="axle_vel_limit" value="10.8696"/>

  <!-- These constants are used to simulate a Traxxas 2056 servo operated at
       6 V. servo_stall_torque is measured in N m. servo_no_load_speed is
       measured in rad/s. -->
  <!-- <xacro:property name="servo_stall_torque" value="0.5649"/>
  <xacro:property name="servo_no_load_speed" value="4.553"/> -->

    <xacro:property name="servo_stall_torque" value="0.5649"/>
  <xacro:property name="servo_no_load_speed" value="4.553"/>

<!-- Materials -->
  <material name="tire_mat">
    <color rgba="0 0 0 1"/>
  </material>
  
<!-- Macros -->
  <!-- Null inertial element. This is needed to make the model work with
       Gazebo. -->
  <xacro:macro name="null_inertial">
    <inertial>
      <mass value="0.001"/>
      <inertia ixx="0.001" ixy="0" ixz="0" iyy="0.001" iyz="0" izz="0.001"/>
    </inertial>
  </xacro:macro>

  <!-- Inertia of a solid cuboid. Width is measured along the x axis, depth
       along the y axis, and height along the z axis. -->
  <xacro:macro name="solid_cuboid_inertial"
               params="width depth height mass *origin">
    <inertial>
      <xacro:insert_block name="origin"/>
      <mass value="${mass}"/>
      <inertia ixx="${mass * (depth * depth + height * height) / 12}"
               ixy="0" ixz="0"
               iyy="${mass * (width * width + height * height) / 12}"
               iyz="0"
               izz="${mass * (width * width + depth * depth) / 12}"/>
    </inertial>
  </xacro:macro>

  <!-- Inertia of a thick-walled cylindrical tube with open ends. Height is
       measured along the z axis, which is the tube's axis. inner_rad and
       outer_rad are the tube's inner and outer radii, respectively. -->
  <xacro:macro name="thick_walled_tube_inertial"
               params="inner_rad outer_rad height mass">
    <inertial>
      <mass value="${mass}"/>
      <inertia ixx="${(1 / 12) * mass * (3 * (inner_rad * inner_rad +
                    outer_rad * outer_rad) + height * height)}"
               ixy="0" ixz="0"
               iyy="${(1 / 12) * mass * (3 * (inner_rad * inner_rad +
                    outer_rad * outer_rad) + height * height)}"
               iyz="0"
               izz="${mass * (inner_rad * inner_rad +
                    outer_rad * outer_rad) / 2}"/>
    </inertial>
  </xacro:macro>


  <xacro:macro name="chassis_joint"
               params="lr_prefix fr_prefix lr_reflect fr_reflect child x y z">
    <joint name="${lr_prefix}_${fr_prefix}_chassis_joint" type="fixed">
      <parent link="chassis"/>
      <child link="${child}"/>
      <origin xyz="${x*fr_reflect} ${y*lr_reflect} ${z}"/>
      <axis xyz="0 0 -1"/>
    </joint>
  </xacro:macro>

<!-- Steering Joint -->

  <xacro:macro name="steering_joint" params="lr_prefix fr_prefix lr_reflect fr_reflect">
    <joint name="${lr_prefix}_${fr_prefix}_steering_joint" type="revolute"> 
    <!-- revolute -->
      <parent link="${lr_prefix}_${fr_prefix}_steering_link"/>
      <child link="${lr_prefix}_${fr_prefix}_axle_carrier"/>
      <axis xyz="0 0 1"/>
      <limit lower="${-Einschlagswinkel}" upper="${Einschlagswinkel}"
             effort="${servo_stall_torque}" velocity="${servo_no_load_speed}"/>
    </joint>
<!-- Transmission -->
    <transmission name="${lr_prefix}_${fr_prefix}_steering_joint_trans">
      <type>transmission_interface/SimpleTransmission</type>
      <joint name="${lr_prefix}_${fr_prefix}_steering_joint">
        <hardwareInterface>hardware_interface/EffortJointInterface</hardwareInterface>
      </joint>
      <actuator name="${lr_prefix}_${fr_prefix}_steering_joint_act">
        <hardwareInterface>hardware_interface/EffortJointInterface</hardwareInterface>
        <mechanicalReduction>1</mechanicalReduction>
      </actuator>
    </transmission>
  </xacro:macro>




<!-- Axle Joint -->
   <xacro:macro name="axle" params="lr_prefix fr_prefix lr_reflect fr_reflect">
    <joint name="${lr_prefix}_${fr_prefix}_axle" type="continuous">
      <parent link="${lr_prefix}_${fr_prefix}_axle_carrier"/>
      <child link="${lr_prefix}_${fr_prefix}_wheel"/>
      <origin rpy="${degrees_90} 0 0"/>
      <axis xyz="0 0 -1"/>
      <limit effort="${axle_eff_limit}" velocity="${axle_vel_limit}"/>
    </joint>
    <transmission name="${lr_prefix}_${fr_prefix}_axle_trans">
      <type>transmission_interface/SimpleTransmission</type>
      <joint name="${lr_prefix}_${fr_prefix}_axle">
        <hardwareInterface>hardware_interface/EffortJointInterface</hardwareInterface>
      </joint>
      <actuator name="${lr_prefix}_${fr_prefix}_axle_act">
        <!-- This hardwareInterface element exists for compatibility
             with ROS Hydro. -->
        <hardwareInterface>hardware_interface/EffortJointInterface</hardwareInterface>
        <mechanicalReduction>1</mechanicalReduction>
      </actuator>
    </transmission>
  </xacro:macro>

  <!-- Wheel -->
    <xacro:macro name="wheel" params="lr_prefix fr_prefix">
    <link name="${lr_prefix}_${fr_prefix}_wheel">
      <visual>
        <origin xyz=" 0 0 0"/>
        <geometry>
          <cylinder radius="${tire_dia / 2}" length="${tire_width}"/>
        </geometry>
        <material name="tire_mat"/>
      </visual>

      <collision>
        <origin xyz="0 0 0"/>
        <geometry>
          <cylinder radius="${tire_dia / 2}" length="${tire_width}"/>
        </geometry>
      </collision>

      <xacro:thick_walled_tube_inertial
          inner_rad="${hub_dia / 2}" outer_rad="${tire_dia / 2}"
          height="${tire_width}" mass="${wheel_mass}"/>
    </link>

    <gazebo reference="${lr_prefix}_${fr_prefix}_wheel">
      <material>Gazebo/Black</material>
    </gazebo>

  </xacro:macro>

<!-- Rear and Front Wheels out of before defined Macros -->
  <!-- Front wheel -->
  <xacro:macro name="front_wheel"
               params="lr_prefix fr_prefix lr_reflect fr_reflect x y z">
    <!-- Chassis Link -->
    <xacro:chassis_joint lr_prefix="${lr_prefix}" fr_prefix="${fr_prefix}"
                 lr_reflect="${lr_reflect}" fr_reflect="${fr_reflect}"
                 child="${lr_prefix}_${fr_prefix}_steering_link" x="${x}" y="${y}" z="${z}"/>
    <!-- Steering Link -->
    <link name="${lr_prefix}_${fr_prefix}_steering_link">
      <xacro:null_inertial/>
    </link>
    <!-- Steering Joint -->
    <xacro:steering_joint lr_prefix="${lr_prefix}" fr_prefix="${fr_prefix}"
                 lr_reflect="${lr_reflect}" fr_reflect="${fr_reflect}"/>

    <!-- Axle Carrier -->
    <link name="${lr_prefix}_${fr_prefix}_axle_carrier">
      <xacro:null_inertial/>
    </link>
    <!-- Axle -->
    <xacro:axle lr_prefix="${lr_prefix}" fr_prefix="${fr_prefix}"
                lr_reflect="${lr_reflect}" fr_reflect="${fr_reflect}"/>
    <!-- Wheel -->
    <xacro:wheel lr_prefix="${lr_prefix}" fr_prefix="${fr_prefix}"/>

  </xacro:macro>


<!-- Rear Wheel -->
<!-- no steerling link and steering joint -->
  <xacro:macro name="rear_wheel"
               params="lr_prefix fr_prefix lr_reflect fr_reflect x y z">
    <!-- Chassis Link -->
    <xacro:chassis_joint lr_prefix="${lr_prefix}" fr_prefix="${fr_prefix}"
                 lr_reflect="${lr_reflect}" fr_reflect="${fr_reflect}"
                 child="${lr_prefix}_${fr_prefix}_axle_carrier" x="${x}" y="${y}" z="${z}"/>
    <!-- Axle Carrier -->
    <link name="${lr_prefix}_${fr_prefix}_axle_carrier">
      <xacro:null_inertial/>
    </link>
    <!-- Axle -->
    <xacro:axle lr_prefix="${lr_prefix}" fr_prefix="${fr_prefix}"
                lr_reflect="${lr_reflect}" fr_reflect="${fr_reflect}"/>
    <!-- Wheel -->
    <xacro:wheel lr_prefix="${lr_prefix}" fr_prefix="${fr_prefix}"/>
  </xacro:macro>
</robot>
